<?xml version="1.0" ?>
<robot xmlns:xacro="http://ros.org/wiki/xacro"
       name="ur5" >
 <xacro:include filename="$(find ur_description)/urdf/common.xacro" />
<xacro:include filename="$(find ur_description)/urdf/common.gazebo.xacro" />
<!--<xacro:include filename="$(find ur_description)/urdf/ur5.urdf.xacro" />-->
<xacro:include filename="$(find ur_description)/urdf/sensors/head_sensor_package.urdf.xacro" />

<link name="world" />

<joint name="world_joint" type="continuous">
  <parent link="world" />
  <child link = "head_plate_frame" />
  <origin xyz="0.0 0.0 0.0" rpy="0.0 0.0 1.57" />
</joint>

<link name="head_plate_frame">

  <inertial>
    <mass value="10.00" />
    <origin xyz="0 0 0" rpy="0 0 0" />
    <inertia ixx="0.001"  ixy="0.0"  ixz="0.0"
             iyy="0.001"  iyz="0.0"
             izz="0.001" />
  </inertial>

  <visual>
    <origin xyz="0 0 0" rpy="0 0 0" />
    <geometry>
      <box size="0.01 0.01 0.01" />
    </geometry>

    <material name="Blue" />
  </visual>

  <collision>
    <origin xyz="0 0 0" rpy="0 0 0" />
    <geometry>
      <box size="0.01 0.01 0.01" />
    </geometry>
  </collision>
</link>

<xacro:pr2_head_sensor_package_v0 name="sensor_mount" hd_frame_name="high_def"
       hd_camera_name="prosilica"
       stereo_name="double_stereo"
       parent="head_plate_frame">
  <origin xyz="0.0 0.0 0.0" rpy="0 0 3.14" />
</xacro:pr2_head_sensor_package_v0>


</robot>
